<?xml version="1.0" encoding="utf-8"?>
<robot
  name="lexium_digital_twin">

  <material name="schneider_green">
    <color rgba="0.0 0.58823 0.22353 1.0" />
  </material>

  <link
    name="base_link">
    <inertial>
      <origin
        xyz="-0.00153899088438138 1.78987042569454E-05 0.0511053058633545"
        rpy="0 0 0" />
      <mass
        value="0.460374564690923" />
      <inertia
        ixx="0.000634228805731141"
        ixy="-9.22181032529603E-08"
        ixz="-1.07985741207947E-05"
        iyy="0.000642978821322286"
        iyz="3.75430185192406E-07"
        izz="0.000822276994247443" />
    </inertial>
    <visual>
      <origin
        xyz="0 0 0"
        rpy="0 0 0" />
      <geometry>
        <mesh
          filename="package://lexium_digital_twin/meshes/base_link.STL" />
      </geometry>
      <material name="schneider_green"/>
    </visual>
    <collision>
      <origin
        xyz="0 0 0"
        rpy="0 0 0" />
      <geometry>
        <mesh
          filename="package://lexium_digital_twin/meshes/base_link.STL" />
      </geometry>
    </collision>
  </link>

  <link
    name="Link_1">
    <inertial>
      <origin
        xyz="2.11210151604379E-07 -0.0032600383999371 0.0611467743193716"
        rpy="0 0 0" />
      <mass
        value="0.884295316293331" />
      <inertia
        ixx="0.00156595774591204"
        ixy="-3.1829281871681E-09"
        ixz="-9.70732401433376E-10"
        iyy="0.00150719780315971"
        iyz="8.90451940070508E-06"
        izz="0.00105380900533969" />
    </inertial>
    <visual>
      <origin
        xyz="0 0 0"
        rpy="0 0 0" />
      <geometry>
        <mesh
          filename="package://lexium_digital_twin/meshes/Link_1.STL" />
      </geometry>
      <material name="schneider_green"/>
    </visual>
    <collision>
      <origin
        xyz="0 0 0"
        rpy="0 0 0" />
      <geometry>
        <mesh
          filename="package://lexium_digital_twin/meshes/Link_1.STL" />
      </geometry>
    </collision>
  </link>
  <joint
    name="Joint_1"
    type="revolute">
    <origin
      xyz="0 0 0.08605"
      rpy="0 0 -3.14159" />
    <parent
      link="base_link" />
    <child
      link="Link_1" />
    <axis
      xyz="0 0 1" />
    <limit
      lower="-3.14159"
      upper="3.14159"
      effort="150.0"
      velocity="3.15" />
  </joint>

  <link
    name="Link_2">
    <inertial>
      <origin
        xyz="1.86433709318299E-07 -0.114019663029007 0.0611583268142885"
        rpy="0 0 0" />
      <mass
        value="2.32175993259425" />
      <inertia
        ixx="0.00457254131391827"
        ixy="-1.96574154576579E-08"
        ixz="9.40548052059898E-09"
        iyy="0.00325786932114449"
        iyz="-3.36892394579144E-06"
        izz="0.00351304152723721" />
    </inertial>
    <visual>
      <origin
        xyz="0 0 0"
        rpy="0 0 0" />
      <geometry>
        <mesh
          filename="package://lexium_digital_twin/meshes/Link_2.STL" />
      </geometry>
      <material name="schneider_green"/>
    </visual>
    <collision>
      <origin
        xyz="0 0 0"
        rpy="0 0 0" />
      <geometry>
        <mesh
          filename="package://lexium_digital_twin/meshes/Link_2.STL" />
      </geometry>
    </collision>
  </link>
  <joint
    name="Joint_2"
    type="revolute">
    <origin
      xyz="0 -0.0505 0.0644999999999995"
      rpy="-1.5707963267949 1.5707963267949 3.14159265358979" />
    <parent
      link="Link_1" />
    <child
      link="Link_2" />
    <axis
      xyz="0 0 -1" />
    <limit
      lower="-3.14159"
      upper="3.14159"
      effort="150.0"
      velocity="3.15" />
  </joint>

  <link
    name="Link_3">
    <inertial>
      <origin
        xyz="2.11022256919615E-07 -0.133284776639748 0.0409329396724559"
        rpy="0 0 0" />
      <mass
        value="1.20330042207005" />
      <inertia
        ixx="0.00386589755228367"
        ixy="4.32607128213095E-08"
        ixz="1.85903438289812E-10"
        iyy="0.00093811456880245"
        iyz="0.000336660411901458"
        izz="0.00362238013552109" />
    </inertial>
    <visual>
      <origin
        xyz="0 0 0"
        rpy="0 0 0" />
      <geometry>
        <mesh
          filename="package://lexium_digital_twin/meshes/Link_3.STL" />
      </geometry>
      <material name="schneider_green"/>
    </visual>
    <collision>
      <origin
        xyz="0 0 0"
        rpy="0 0 0" />
      <geometry>
        <mesh
          filename="package://lexium_digital_twin/meshes/Link_3.STL" />
      </geometry>
    </collision>
  </link>
  <joint
    name="Joint_3"
    type="revolute">
    <origin
      xyz="0 -0.24600000094683 -0.00350000000001006"
      rpy="-3.14159265358979 0 -3.14159265358979" />
    <parent
      link="Link_2" />
    <child
      link="Link_3" />
    <axis
      xyz="0 0 1" />
    <limit
      lower="-3.14159"
      upper="3.14159"
      effort="150.0"
      velocity="3.15" />
  </joint>

  <link
    name="Link_4">
    <inertial>
      <origin
        xyz="6.63581591882425E-07 0.0140954810950097 0.0384066562704616"
        rpy="0 0 0" />
      <mass
        value="0.493200863231089" />
      <inertia
        ixx="0.000501550219737654"
        ixy="-3.21596725516391E-10"
        ixz="7.73858274783939E-09"
        iyy="0.000324066408173854"
        iyz="-6.21495450181184E-05"
        izz="0.000479035823680177" />
    </inertial>
    <visual>
      <origin
        xyz="0 0 0"
        rpy="0 0 0" />
      <geometry>
        <mesh
          filename="package://lexium_digital_twin/meshes/Link_4.STL" />
      </geometry>
      <material name="schneider_green"/>
    </visual>
    <collision>
      <origin
        xyz="0 0 0"
        rpy="0 0 0" />
      <geometry>
        <mesh
          filename="package://lexium_digital_twin/meshes/Link_4.STL" />
      </geometry>
    </collision>
  </link>
  <joint
    name="Joint_4"
    type="revolute">
    <origin
      xyz="0 -0.228000000001584 -0.0244999999969376"
      rpy="-3.14159265356148 0 -1.5707963267949" />
    <parent
      link="Link_3" />
    <child
      link="Link_4" />
    <axis
      xyz="0 0 -1" />
    <limit
      lower="-3.14159"
      upper="3.14159"
      effort="28.0"
      velocity="3.2" />
  </joint>

  <link
    name="Link_5">
    <inertial>
      <origin
        xyz="-2.19383742788647E-06 -0.00676921996752099 0.0385949901802433"
        rpy="0 0 0" />
      <mass
        value="0.55156964581296" />
      <inertia
        ixx="0.00101051555001167"
        ixy="1.61103782987192E-09"
        ixz="-1.04472007475205E-08"
        iyy="0.000360478219660431"
        iyz="1.65612456860953E-05"
        izz="0.000981985301860736" />
    </inertial>
    <visual>
      <origin
        xyz="0 0 0"
        rpy="0 0 0" />
      <geometry>
        <mesh
          filename="package://lexium_digital_twin/meshes/Link_5.STL" />
      </geometry>
      <material name="schneider_green"/>
    </visual>
    <collision>
      <origin
        xyz="0 0 0"
        rpy="0 0 0" />
      <geometry>
        <mesh
          filename="package://lexium_digital_twin/meshes/Link_5.STL" />
      </geometry>
    </collision>
  </link>
  <joint
    name="Joint_5"
    type="revolute">
    <origin
      xyz="0 0.0760000000011137 0.0414999999977316"
      rpy="1.57079632682321 0 -3.14159265358979" />
    <parent
      link="Link_4" />
    <child
      link="Link_5" />
    <axis
      xyz="0 0 1" />
    <limit
      lower="-3.14159"
      upper="3.14159"
      effort="28.0"
      velocity="3.2" />
  </joint>

  <link
    name="Link_6">
    <inertial>
      <origin
        xyz="2.04521118006405E-05 -5.00312640405731E-05 0.0134113824379624"
        rpy="0 0 0" />
      <mass
        value="0.0951327910810692" />
      <inertia
        ixx="3.36064368849105E-05"
        ixy="2.00195929980298E-07"
        ixz="3.17141866321017E-08"
        iyy="3.36666169020005E-05"
        iyz="8.89684072947432E-08"
        izz="5.51967331435198E-05" />
    </inertial>
    <visual>
      <origin
        xyz="0 0 0"
        rpy="0 0 0" />
      <geometry>
        <mesh
          filename="package://lexium_digital_twin/meshes/Link_6.STL" />
      </geometry>
      <material name="schneider_green"/>
    </visual>
    <collision>
      <origin
        xyz="0 0 0"
        rpy="0 0 0" />
      <geometry>
        <mesh
          filename="package://lexium_digital_twin/meshes/Link_6.STL" />
      </geometry>
    </collision>
  </link>
  <joint
    name="Joint_6"
    type="revolute">
    <origin
      xyz="0 -0.0760000000025846 0.0414999999985123"
      rpy="-1.5707963267949 0.785398163 -3.14159265358979" />
    <parent
      link="Link_5" />
    <child
      link="Link_6" />
    <axis
      xyz="0 0 1" />
    <limit
      lower="-3.14159"
      upper="3.14159"
      effort="28.0"
      velocity="3.2" />
  </joint>
</robot>